[2024-08-07T15:33:27.105-0300] {local_task_job_runner.py:120} INFO - ::group::Pre task execution logs
[2024-08-07T15:33:27.120-0300] {taskinstance.py:2076} INFO - Dependencies all met for dep_context=non-requeueable deps ti=<TaskInstance: ETL_SIM.atlas_connection scheduled__2024-08-06T00:00:00+00:00 [queued]>
[2024-08-07T15:33:27.127-0300] {taskinstance.py:2076} INFO - Dependencies all met for dep_context=requeueable deps ti=<TaskInstance: ETL_SIM.atlas_connection scheduled__2024-08-06T00:00:00+00:00 [queued]>
[2024-08-07T15:33:27.128-0300] {taskinstance.py:2306} INFO - Starting attempt 1 of 1
[2024-08-07T15:33:27.148-0300] {taskinstance.py:2330} INFO - Executing <Task(AtlasConnectionCheckOperator): atlas_connection> on 2024-08-06 00:00:00+00:00
[2024-08-07T15:33:27.153-0300] {standard_task_runner.py:63} INFO - Started process 7816 to run task
[2024-08-07T15:33:27.157-0300] {standard_task_runner.py:90} INFO - Running: ['airflow', 'tasks', 'run', 'ETL_SIM', 'atlas_connection', 'scheduled__2024-08-06T00:00:00+00:00', '--job-id', '1046', '--raw', '--subdir', 'DAGS_FOLDER/ETL_DO.py', '--cfg-path', '/tmp/tmp8xs0y738']
[2024-08-07T15:33:27.159-0300] {standard_task_runner.py:91} INFO - Job 1046: Subtask atlas_connection
[2024-08-07T15:33:27.198-0300] {task_command.py:426} INFO - Running <TaskInstance: ETL_SIM.atlas_connection scheduled__2024-08-06T00:00:00+00:00 [running]> on host LAPTOP-NDHI6BI3.
[2024-08-07T15:33:27.280-0300] {taskinstance.py:2648} INFO - Exporting env vars: AIRFLOW_CTX_DAG_OWNER='airflow' AIRFLOW_CTX_DAG_ID='ETL_SIM' AIRFLOW_CTX_TASK_ID='atlas_connection' AIRFLOW_CTX_EXECUTION_DATE='2024-08-06T00:00:00+00:00' AIRFLOW_CTX_TRY_NUMBER='1' AIRFLOW_CTX_DAG_RUN_ID='scheduled__2024-08-06T00:00:00+00:00'
[2024-08-07T15:33:27.281-0300] {taskinstance.py:430} INFO - ::endgroup::
[2024-08-07T15:35:40.060-0300] {ETL_DO.py:38} ERROR - Erro ao conectar-se ao Apache Atlas: HTTPConnectionPool(host='10.100.100.61', port=21000): Max retries exceeded with url: / (Caused by ConnectTimeoutError(<urllib3.connection.HTTPConnection object at 0x7f8eb82cdd50>, 'Connection to 10.100.100.61 timed out. (connect timeout=None)'))
[2024-08-07T15:35:40.062-0300] {taskinstance.py:441} INFO - ::group::Post task execution logs
[2024-08-07T15:35:40.064-0300] {taskinstance.py:2905} ERROR - Task failed with exception
Traceback (most recent call last):
  File "/home/jamilsonfs/.local/lib/python3.10/site-packages/airflow/models/taskinstance.py", line 465, in _execute_task
    result = _execute_callable(context=context, **execute_callable_kwargs)
  File "/home/jamilsonfs/.local/lib/python3.10/site-packages/airflow/models/taskinstance.py", line 432, in _execute_callable
    return execute_callable(context=context, **execute_callable_kwargs)
  File "/home/jamilsonfs/.local/lib/python3.10/site-packages/airflow/models/baseoperator.py", line 401, in wrapper
    return func(self, *args, **kwargs)
  File "/home/jamilsonfs/airflow/dags/ETL_DO.py", line 43, in execute
    raise Exception("Falha na conexão com o Apache Atlas.")
Exception: Falha na conexão com o Apache Atlas.
[2024-08-07T15:35:40.099-0300] {taskinstance.py:1206} INFO - Marking task as FAILED. dag_id=ETL_SIM, task_id=atlas_connection, run_id=scheduled__2024-08-06T00:00:00+00:00, execution_date=20240806T000000, start_date=20240807T183327, end_date=20240807T183540
[2024-08-07T15:35:40.129-0300] {standard_task_runner.py:110} ERROR - Failed to execute job 1046 for task atlas_connection (Falha na conexão com o Apache Atlas.; 7816)
[2024-08-07T15:35:40.143-0300] {local_task_job_runner.py:240} INFO - Task exited with return code 1
[2024-08-07T15:35:40.173-0300] {taskinstance.py:3503} INFO - 0 downstream tasks scheduled from follow-on schedule check
[2024-08-07T15:35:40.183-0300] {local_task_job_runner.py:222} INFO - ::endgroup::
