[2024-08-05T18:48:51.684-0300] {local_task_job_runner.py:120} INFO - ::group::Pre task execution logs
[2024-08-05T18:48:51.699-0300] {taskinstance.py:2076} INFO - Dependencies all met for dep_context=non-requeueable deps ti=<TaskInstance: ETL_SIM.check_atlas_connection manual__2024-08-05T21:47:38.495224+00:00 [queued]>
[2024-08-05T18:48:51.705-0300] {taskinstance.py:2076} INFO - Dependencies all met for dep_context=requeueable deps ti=<TaskInstance: ETL_SIM.check_atlas_connection manual__2024-08-05T21:47:38.495224+00:00 [queued]>
[2024-08-05T18:48:51.706-0300] {taskinstance.py:2306} INFO - Starting attempt 1 of 1
[2024-08-05T18:48:51.723-0300] {taskinstance.py:2330} INFO - Executing <Task(AtlasMetadataOperator): check_atlas_connection> on 2024-08-05 21:47:38.495224+00:00
[2024-08-05T18:48:51.727-0300] {standard_task_runner.py:63} INFO - Started process 51057 to run task
[2024-08-05T18:48:51.730-0300] {standard_task_runner.py:90} INFO - Running: ['airflow', 'tasks', 'run', 'ETL_SIM', 'check_atlas_connection', 'manual__2024-08-05T21:47:38.495224+00:00', '--job-id', '1003', '--raw', '--subdir', 'DAGS_FOLDER/ETL_DO.py', '--cfg-path', '/tmp/tmp5tcci7pl']
[2024-08-05T18:48:51.731-0300] {standard_task_runner.py:91} INFO - Job 1003: Subtask check_atlas_connection
[2024-08-05T18:48:51.774-0300] {task_command.py:426} INFO - Running <TaskInstance: ETL_SIM.check_atlas_connection manual__2024-08-05T21:47:38.495224+00:00 [running]> on host LAPTOP-NDHI6BI3.
[2024-08-05T18:48:51.848-0300] {taskinstance.py:2648} INFO - Exporting env vars: AIRFLOW_CTX_DAG_OWNER='airflow' AIRFLOW_CTX_DAG_ID='ETL_SIM' AIRFLOW_CTX_TASK_ID='check_atlas_connection' AIRFLOW_CTX_EXECUTION_DATE='2024-08-05T21:47:38.495224+00:00' AIRFLOW_CTX_TRY_NUMBER='1' AIRFLOW_CTX_DAG_RUN_ID='manual__2024-08-05T21:47:38.495224+00:00'
[2024-08-05T18:48:51.850-0300] {taskinstance.py:430} INFO - ::endgroup::
[2024-08-05T18:48:51.931-0300] {ETL_DO.py:47} ERROR - Erro ao registrar metadados no Atlas: module 'requests' has no attribute 'create_entity'
[2024-08-05T18:48:51.931-0300] {taskinstance.py:441} INFO - ::group::Post task execution logs
[2024-08-05T18:48:51.932-0300] {taskinstance.py:2905} ERROR - Task failed with exception
Traceback (most recent call last):
  File "/home/jamilsonfs/.local/lib/python3.10/site-packages/airflow/models/taskinstance.py", line 465, in _execute_task
    result = _execute_callable(context=context, **execute_callable_kwargs)
  File "/home/jamilsonfs/.local/lib/python3.10/site-packages/airflow/models/taskinstance.py", line 432, in _execute_callable
    return execute_callable(context=context, **execute_callable_kwargs)
  File "/home/jamilsonfs/.local/lib/python3.10/site-packages/airflow/models/baseoperator.py", line 401, in wrapper
    return func(self, *args, **kwargs)
  File "/home/jamilsonfs/airflow/dags/ETL_DO.py", line 44, in execute
    response = atlas.create_entity(self.metadata)
  File "/home/jamilsonfs/.local/lib/python3.10/site-packages/atlasclient/client.py", line 100, in __getattr__
    if getattr(requests, attr):
AttributeError: module 'requests' has no attribute 'create_entity'
[2024-08-05T18:48:51.944-0300] {taskinstance.py:1206} INFO - Marking task as FAILED. dag_id=ETL_SIM, task_id=check_atlas_connection, run_id=manual__2024-08-05T21:47:38.495224+00:00, execution_date=20240805T214738, start_date=20240805T214851, end_date=20240805T214851
[2024-08-05T18:48:51.959-0300] {standard_task_runner.py:110} ERROR - Failed to execute job 1003 for task check_atlas_connection (module 'requests' has no attribute 'create_entity'; 51057)
[2024-08-05T18:48:51.983-0300] {local_task_job_runner.py:240} INFO - Task exited with return code 1
[2024-08-05T18:48:52.002-0300] {taskinstance.py:3503} INFO - 0 downstream tasks scheduled from follow-on schedule check
[2024-08-05T18:48:52.012-0300] {local_task_job_runner.py:222} INFO - ::endgroup::
